/home/wooyeon/Multimodal-Augmentation/GMMIX/CLIP/clip/clip.py:23: UserWarning: PyTorch version 1.7.1 or higher is recommended
  warnings.warn("PyTorch version 1.7.1 or higher is recommended")
loading annotations into memory...
Done (t=1.10s)
creating index...
index created!
loading annotations into memory...
Done (t=0.04s)
creating index...
index created!
loading annotations into memory...
Done (t=0.03s)
creating index...
index created!
length of train set :  118287
Traceback (most recent call last):
  File "/home/iknow/anaconda3/envs/ma/lib/python3.9/site-packages/pandas/core/indexes/base.py", line 3803, in get_loc
    return self._engine.get_loc(casted_key)
  File "pandas/_libs/index.pyx", line 138, in pandas._libs.index.IndexEngine.get_loc
  File "pandas/_libs/index.pyx", line 165, in pandas._libs.index.IndexEngine.get_loc
  File "pandas/_libs/hashtable_class_helper.pxi", line 5745, in pandas._libs.hashtable.PyObjectHashTable.get_item
  File "pandas/_libs/hashtable_class_helper.pxi", line 5753, in pandas._libs.hashtable.PyObjectHashTable.get_item
KeyError: 'type'
The above exception was the direct cause of the following exception:
Traceback (most recent call last):
  File "/home/wooyeon/Multimodal-Augmentation/GMMIX/clip_mod_sph.py", line 932, in <module>
    flickrtest          = FlickerDataset('/home/wooyeon/Multimodal-Augmentation/GMMIX/dataset/flicker/flickr30k_images/flickr30k_images',transform=preprocess).filter_df("test")
  File "/home/wooyeon/Multimodal-Augmentation/GMMIX/dataset.py", line 40, in filter_df
    self.caption_df = self.caption_df[self.caption_df['type'] == name]
  File "/home/iknow/anaconda3/envs/ma/lib/python3.9/site-packages/pandas/core/frame.py", line 3805, in __getitem__
    indexer = self.columns.get_loc(key)
  File "/home/iknow/anaconda3/envs/ma/lib/python3.9/site-packages/pandas/core/indexes/base.py", line 3805, in get_loc
    raise KeyError(key) from err
KeyError: 'type'